Workbook

Sheet TIẾN ĐỘ TỔNG THỂ (ROADMAP)
A1: BẢNG KẾ HOẠCH & TIẾN ĐỘ TỔNG THỂ ĐA DỰ ÁN
A3: TỔNG SỐ HẠNG MỤC | D3: ĐÃ HOÀN THÀNH | G3: ĐANG THỰC HIỆN | J3: CHẬM TIẾN ĐỘ | M3: TỶ LỆ HOÀN THÀNH CHUNG
A4: =COUNTIF(A8:A93, "TSK*") -> 58 | D4: =COUNTIF(G8:G93, "Đã hoàn thành") -> 46 | G4: =COUNTIF(G8:G93, "Đang thực hiện") -> 6 | J4: =COUNTIF(G8:G93, "Chậm tiến độ") -> 0 | M4: =IFERROR(D4/A4, 0) -> 0.79310345
A6: THÔNG TIN DỰ ÁN & CÔNG VIỆC PHÂN CÔNG | I6: THÁNG 08/2026 | M6: THÁNG 09/2026 | Q6: THÁNG 10/2026 | U6: THÁNG 11/2026 | Y6: THÁNG 12/2026
A7: Mã việc | B7: Dự án & Hạng mục công việc | C7: Mục tiêu / Tiêu chí đầu ra | D7: Đầu mối | E7: Phối hợp | F7: Hạn chót | G7: Trạng thái | H7: Tiến độ % | I7: T1 (1-7) | J7: T2 (8-14) | K7: T3 (15-21) | L7: T4 (22-31) | M7: T1 (1-7) | N7: T2 (8-14) | O7: T3 (15-21) | P7: T4 (22-30) | Q7: T1 (1-7) | R7: T2 (8-14) | S7: T3 (15-21) | T7: T4 (22-31) | U7: T1 (1-7) | V7: T2 (8-14) | W7: T3 (15-21) | X7: T4 (22-30) | Y7: T1 (1-7) | Z7: T2 (8-14) | AA7: T3 (15-21) | AB7: T4 (22-31)
A8: 📁 DỰ ÁN 01: PHÂN TÍCH CUỘC GỌI GIAO DỊCH VIÊN
A9: TSK-01 | B9: Xác định phạm vi, mục tiêu & đội ngũ triển khai hệ thống AI phân tích cuộc gọi | C9: - Mục tiêu: Xây dựng hệ thống AI tự động phân tích file ghi âm sau cuộc gọi của Giao dịch viên (GDV), phát hiện sớm cảm xúc tiêu cực của khách hàng, tự động chấm điểm QA theo scorecard VOC, cảnh báo vi phạm quy trình và cung cấp bằng chứng có timestamp. - Phạm vi: Triển khai 2 tháng (Tháng 8/2026 làm Core AI & UI MVP; Tháng 9/2026 làm Dashboard, Tích hợp CRM & Go-live). | D9: An Thanh | F9: 46241 | G9: Đã hoàn thành | H9: 1 | I9: Xong | J9: Xong | K9: - | L9: -
A10: TSK-02 | B10: Chuẩn hóa bộ tiêu chí chấm điểm VOC Scorecard & Quy tắc đánh giá QA/QC | C10: - Bộ 300 từ khóa QA phân loại theo nhóm: Chào hỏi, thái độ, tư vấn giải pháp, xử lý khiếu nại, cam kết, chào kết thúc. - Scorecard VOC V1: Bộ tiêu chí chấm điểm GDV có trọng số, định nghĩa lỗi nghiêm trọng (Zero-tolerance / Auto-fail), ngưỡng cảnh báo không hài lòng. | D10: An Thanh | F10: 46246 | G10: Đã hoàn thành | H10: 1 | I10: Xong | J10: Xong | K10: Xong | L10: Xong
A11: TSK-03 | B11: Xây dựng Taxonomy nhãn phân tích, ý định (Intent) & Cảm xúc (Emotion) | C11: - Bộ nhãn phân loại ý định khách hàng (Hỏi giá, kỹ thuật thiết bị, bảo hành, phản ánh sự cố, đặt hàng, thanh toán). - Bộ nhãn cảm xúc 4 mức: Tích cực (Positive), Bình thường (Neutral), Không hài lòng (Negative), Cực kỳ bức xúc (Angry/Urgent). - Ma trận phân quyền 4 vai trò: Admin, Leader, QA/QC, GDV với Data Scope (ALL, UNIT, TEAM, AGENT, SELF). | D11: An Thanh | F11: 46247 | G11: Đã hoàn thành | H11: 1 | K11: Xong | L11: Xong
A12: TSK-04 | B12: Xây dựng khung Modular Monolith, Database Schema & Authentication/RBAC | C12: - Khởi tạo backend FastAPI / Python 3.12 với cấu trúc Domain-Driven Modular. - Thiết kế Database Models & Alembic Migrations: Users, Roles, Permissions, Calls, ProcessingJobs, AudioSegments, Transcripts, AnalysisResults, Scorecards, Scores, AuditLogs. - Xây dựng Module Authentication JWT + Phân quyền RBAC & Data Scoping theo tổ chức. | D12: An Thanh | F12: 46248 | G12: Đã hoàn thành | H12: 1 | K12: Xong | L12: Xong
A13: TSK-05 | B13: Thu thập, làm sạch & chuẩn hóa tập dữ liệu âm thanh mẫu | C13: - Thu thập 100+ cuộc gọi mẫu thực tế (đa kênh stereo/mono, các định dạng wav, mp3, m4a, ogg, pcm). - Pipeline tiền xử lý âm thanh: Chuẩn hóa sampling rate 16kHz Mono/Stereo, bộ lọc nhiễu âm lượng, VAD (Voice Activity Detection) cắt khoảng lặng, tách kênh thoại GDV - Khách hàng. | D13: An Thanh | F13: 46254 | G13: Đã hoàn thành | H13: 1 | K13: Xong | L13: Xong
A14: TSK-06 | B14: Phát triển Pipeline Speech-to-Text (STT) & Speaker Diarization tiếng Việt | C14: - Tích hợp Shepra Onnx tối ưu phiên âm tiếng Việt tổng đài. - Cơ chế Speaker Diarization: Tách chính xác lời thoại GDV vs Khách hàng theo từng turn đối thoại. - Trích xuất Transcript chi tiết từng câu kèm Timestamp chính xác từng giây, confidence score và metadata âm thanh. | D14: An Thanh | F14: 46255 | G14: Đã hoàn thành | H14: 1 | K14: Xong | L14: Xong
A15: TSK-07 | B15: Phát triển Module Phân tích Cảm xúc Âm thanh & Chỉ số Giọng điệu (Acoustic) | C15: - Trích xuất chỉ số âm thanh khách quan: tỉ lệ im lặng và các khoảng chết có mốc thời gian; số lần chồng tiếng và cướp lời quy kết được về từng vai; tốc độ nói (âm tiết/phút, tách riêng tốc độ phát âm sau khi trừ im lặng); cao độ và cường độ đo theo từng lượt nói. - Phân tích hai kênh độc lập: kênh văn bản cho nội dung cảm xúc (hài lòng → bức xúc), kênh âm thanh cho ngữ điệu (điềm đạm / to tiếng). - Gắn nhãn theo từng đoạn hội thoại, hai trục song song trên cùng trục thời gian, kèm mức phủ công bố theo thời lượng. - Hợp nhất hai kênh cảm xúc và ngữ điệu để phát hiện điểm bùng phát xung đột. | D15: An Thanh | F15: 46256 | G15: Chưa thực hiện
A16: TSK-08 | B16: Phát triển NLP Intent, Tóm tắt ngữ cảnh & Rule Engine kiểm tra tuân thủ | C16: - Rule Engine xử lý 300+ từ khóa nghiệp vụ Rạng Đông, kiểm tra quy chuẩn chào hỏi/kết thúc/tư vấn. - NLP Module: Phân loại nhu cầu chính của khách hàng, trích xuất vấn đề/sản phẩm được đề cập. - Tóm tắt tự động cuộc gọi (LLM Structured Summary: Nội dung chính, cam kết của GDV, hành động tiếp theo Next Action) qua Gemini API / Local LLM Adapter. | D16: An Thanh | F16: 46257 | G16: Đã hoàn thành | H16: 1 | J16: Xong | K16: Xong
A17: TSK-09 | B17: Module Quản lý Cuộc gọi, Upload hàng loạt & Worker xử lý Async | C17: - API Upload file ghi âm đơn lẻ & upload theo lô (Batch upload tới 500MB/file, hỗ trợ zip/folder). - RabbitMQ Worker xử lý bất đồng bộ: Ingestion -> VAD -> STT -> Emotion -> NLP -> Scoring -> Notify. - Quản lý trạng thái ProcessingJob, hỗ trợ Reprocess khi cập nhật model hoặc rule mới. | D17: An Thanh | F17: 46258 | G17: Đang thực hiện | H17: 0.5
A18: TSK-10 | B18: Module Chấm điểm Tự động theo Scorecard VOC & Quản trị Tiêu chí | C18: - Engine tự động tính điểm theo Scorecard có trọng số (Thái độ, Kỹ năng, Nghiệp vụ, Xử lý khiếu nại). - Tự động áp dụng quy tắc Zero-tolerance (Lỗi nghiêm trọng -> 0 điểm hoặc Cảnh báo đỏ). - Cung cấp minh chứng (Evidence grounding): Gắn link chính xác từng đoạn transcript & timestamp cho mỗi tiêu chí được chấm. | D18: An Thanh | F18: 46259 | G18: Đã hoàn thành | H18: 1 | J18: Xong | K18: Xong
A19: TSK-11 | B19: Giao diện Danh sách cuộc gọi, Bộ lọc đa chiều & Quản lý phân quyền | C19: - Màn hình Danh sách cuộc gọi: Tìm kiếm theo ngày, GDV, phòng ban, điểm số, mức độ hài lòng, từ khóa vi phạm, trạng thái QC. - Màn hình Upload & Theo dõi tiến trình xử lý real-time. - Màn hình Quản lý Tài khoản, Vai trò & Ma trận phân quyền 4 cấp. | D19: An Thanh | F19: 46260 | G19: Đã hoàn thành | H19: 1 | J19: Xong | K19: Xong | L19: Xong
A20: TSK-12 | B20: Giao diện Chi tiết cuộc gọi, Audio Player đồng bộ Transcript & QC Review | C20: - Audio Player trực quan: Waveform hiển thị 2 kênh (GDV / Khách hàng), nhảy đến đúng timestamp khi bấm vào transcript. - Transcript tương tác: Highlight từ khóa, nhãn cảm xúc, vi phạm quy trình theo mã màu trực quan. - Bảng chấm điểm QA/QC: Cho phép chuyên viên QC xác nhận điểm AI, điều chỉnh điểm từng tiêu chí, sửa speaker/transcript, nhập ghi chú đánh giá và lưu Audit Log. | D20: An Thanh | F20: 46261 | G20: Đã hoàn thành | H20: 1 | K20: Xong | L20: Xong
A21: TSK-13 | B21: Dashboard Báo cáo Quản trị & Phân tích chất lượng CSKH | C21: - Dashboard Tổng quan: Biểu đồ số lượng cuộc gọi, Tỷ lệ hài lòng CSAT, Tỷ lệ xử lý lần đầu FCR, Điểm trung bình GDV theo thời gian. - Dashboard Phân tích GDV: Xếp hạng GDV theo điểm QA, phân tích điểm mạnh/yếu theo từng tiêu chí, tỷ lệ ngắt lời/nói đè. - Dashboard Phân tích Khách hàng & Sản phẩm: Top vấn đề khiếu nại, nhóm sản phẩm được hỏi nhiều nhất, xu hướng cảm xúc khách hàng. - Tính năng Xuất Báo cáo Excel / PDF chi tiết. | D21: An Thanh | E21: CTV(Hưng) | F21: 46268 | G21: Đang thực hiện | K21: Đang làm | L21: Đang làm | M21: Đang làm
A22: TSK-14 | B22: Module Quản trị Cấu hình: Scorecard, Bộ từ khóa, Ngưỡng cảnh báo & LLM Prompting | C22: - Giao diện tạo/sửa Scorecard, phân bổ trọng số tiêu chí động, quản lý phiên bản (Versioning). - Giao diện quản lý Danh mục từ khóa QA, từ khóa nhạy cảm, regex pattern. - Giao diện cấu hình Prompt Template cho tóm tắt và insight AI, cài đặt ngưỡng cảnh báo khẩn cấp. | D22: An Thanh | E22: CTV(Hưng) | F22: 46268 | G22: Đang thực hiện | K22: Đang làm | L22: Đang làm | M22: Đang làm
A23: TSK-15 | B23: Xây dựng bộ Test case & Kiểm thử Kỹ thuật nội bộ TTDL&ĐHS | C23: - Bộ Test suite tự động (Unit test, Integration test, E2E flow với Playwright). - Kiểm thử tải (Stress test): Xử lý đồng thời 50 cuộc gọi dung lượng lớn, đo latency STT & bộ nhớ GPU. - Kiểm tra an toàn bảo mật, chống tấn công OWASP, kiểm soát quyền truy cập dữ liệu. | D23: An Thanh | F23: 46264 | G23: Đang thực hiện
A24: 📁 DỰ ÁN 02: OPENWEBUI
A25: TSK-01 | B25: Dựng Tab Overview cho lãnh đạo | C25: Leader có thể xem được thông tin tổng quan mà không cần phải chuyển qua lại giữa các tab | D25: Tuấn | F25: 20/07/2026 | G25: Đã hoàn thành | H25: 1
A26: TSK-02 | B26: Thống nhất cách gom số liệu audit log trên toàn bộ dashboard | C26: mọi tab trả về cũng một con số trên cùng một metric, đạt tính đồng bộ cao | D26: Tuấn | F26: 21/07/2026 | G26: Đã hoàn thành | H26: 1
A27: TSK-03 | B27: Chỉ tiêu Request & Call | C27: Trả lời được: tốc độ phản hồi, đơn giá, mức độ tải của hệ thống theo giờ | D27: Tuấn | F27: 24/07/2026 | G27: Đã hoàn thành | H27: 1
A28: TSK-04 | B28: Chỉ tiêu Adoption | C28: Biết đã cấp được bao nhiêu tài khoản và mức độ sử dụng của các tài khoản đó | D28: Tuấn | F28: 24/07/2026 | G28: Đã hoàn thành | H28: 1
A29: TSK-05 | B29: Chỉ tiêu Model | C29: Biết mức độ sử dụng của môt model và những người dùng, phòng ban nào sử dụng nó | D29: Tuấn | F29: 24/07/2026 | G29: Đã hoàn thành | H29: 1
A30: TSK-06 | B30: Tab Provider - theo dõi credit trả trước | C30: biết provider nào sắp cạn creadit để bổ sung | D30: Tuấn | F30: 27/07/2026 | G30: Đã hoàn thành | H30: 1
A31: TSK-07 | B31: Chuẩn hóa chỉ tiêu phòng ban theo quy mô | C31: So được phòng ban theo từng người | D31: Tuấn | E31: Chí Thanh | F31: 28/07/2026 | G31: Đã hoàn thành | H31: 1
A32: TSK-08 | B32: Chỉ tiêu về mức độ hài lòng của người dùng | C32: điểm số mức độ hài lòng hiển thị chính xác, biết tỉ lệ câu trả lời nhận được đánh giá | D32: Tuấn | E32: Chí Thanh | F32: 30/07/2026 | G32: Đã hoàn thành | H32: 1
A33: TSK-09 | B33: RAG Retrieval & độ phủ knowledge base | C33: Hit-rate được tính chính xác, và đo được mức độ áp dụng của knowledge có rộng rãi hay không | D33: Tuấn | E33: Chí Thanh | F33: 31/07/2026 | G33: Đã hoàn thành | H33: 1
A34: TSK-10 | B34: Giám sát vận hành và xác định IP truy cập | C34: Quản trị viên có thể biết được sức khỏe của hệ thống, và ai gọi vào hệ thống | D34: Tuấn | E34: Chí Thanh | F34: 46061 | G34: Đã hoàn thành | H34: 1 | I34: Xong
A35: TSK-11 | B35: Hạ tầng so sánh kỳ trước & cùng kỳ | C35: các chỉ tiêu quan trong đều có so kỳ trước cùng kỳ, không cần phải chuyển mốc thời gian | D35: Tuấn | E35: Chí Thanh | F35: 46089 | G35: Đã hoàn thành | H35: 1 | J35: Xong
A36: TSK-12 | B36: Chuẩn hóa nhãn chỉ tiêu của toàn dashboard | C36: Nhãn gọi đúng đại lượng của con số bên dưới, không bỏ sót bất cứ con số nào | D36: Tuấn | E36: Chí Thanh | F36: 46089 | G36: Đã hoàn thành | H36: 1 | I36: Xong
A37: TSK-13 | B37: Tách quản trị tài khoản khỏi tab báo cáo | C37: Tab User đưa được cho người chỉ cần xem, Sync now ghi thật vào trong db | D37: Tuấn | E37: Chí Thanh | F37: 46303 | G37: Đã hoàn thành | H37: 1 | J37: Xong
A38: TSK-14 | B38: Bộ tài liệu khảo sát và bàn giao dashboard | C38: người sau độc tài liệu là có thể làm tiếp được không cần dò lại code | D38: Tuấn | E38: Chí Thanh | F38: 10/0802026 | G38: Đã hoàn thành | H38: 1 | J38: Xong
A39: 📁 DỰ ÁN 03: AI RADAR IMPACT
A40: TSK-01 | B40: Đáp ứng nhu cầu cập nhật thông tin liên tục qua việc gửi thông báo qua mail | C40: Khởi tạo trước bot gửi gmail để kiểm thử: + Lựa chọn chuyên môn để được gửi đúng bài báo liên quan + Tự động gửi các alert (cấp thiết) cho security sau khi tiến hành crawl + Tương tác hỏi đáp thẳng trong khung hội thoại. | D40: Hưng | E40: An Thanh | F40: 24/07/2026 | G40: Tạm dừng | H40: 0.8 | K40: -
A41: TSK-02 | B41: Chatbot UI trên dashboard | C41: Chatbot đáp ứng được các yêu cầu: + Thời gian phản hồi dưới 5s + Cửa sổ ngữ cảnh đủ rộng(5 bài báo) + Khả năng truy xuất dữ liệu insight có trong db | D41: Hưng | E41: An Thanh | F41: 24/07/2026 | G41: Tạm dừng | H41: 0.8 | K41: -
A42: TSK-03 | B42: Phương thức /cách thức tính năng tool | C42: Kiểm tra hiển thị Dark Mode, độ tương phản của chữ và màu sắc các nhãn (badges) theo feedback người dùng. | D42: An Thanh | E42: Chí Thanh | F42: 15/08/2026 | G42: Đã hoàn thành | H42: 1 | K42: Xong
...

Sheet BÁO CÁO
A1: BÁO CÁO TỔNG QUAN TIẾN ĐỘ THEO DỰ ÁN & NHÂN SỰ
A3: 1. TIẾN ĐỘ THEO TỪNG DỰ ÁN (PROJECT PORTFOLIO)
A4: STT | B4: Tên Dự Án | C4: Số đầu việc | D4: Đã xong | E4: Đang làm | F4: Chậm trễ | G4: Chưa làm | H4: Tiến độ % | I4: Tình trạng Dự án
A5: 1 | B5: Dự án 01: Triển khai Kế hoạch & Vận hành Báo cáo | C5: =COUNTA('TIẾN ĐỘ TỔNG THỂ (ROADMAP)'!A9:A12) -> 4 | D5: =COUNTIF('TIẾN ĐỘ TỔNG THỂ (ROADMAP)'!G9:G12, "Đã hoàn thành") -> 4 | E5: =COUNTIF('TIẾN ĐỘ TỔNG THỂ (ROADMAP)'!G9:G12, "Đang thực hiện") -> 0 | F5: =COUNTIF('TIẾN ĐỘ TỔNG THỂ (ROADMAP)'!G9:G12, "Chậm tiến độ") -> 0 | G5: =COUNTIF('TIẾN ĐỘ TỔNG THỂ (ROADMAP)'!G9:G12, "Chưa thực hiện") -> 0 | H5: =IFERROR(D5/C5, 0) -> 1 | I5: =IF(C5=0, "Chưa có việc", IF(F5>0, "⚠️ Có việc chậm trễ", IF(H5=1, "✅ Đã hoàn thành", "🟢 Đúng kế hoạch"))) -> ✅ Đã hoàn thành
A6: 2 | B6: Dự án 02: Nâng cấp Hạ tầng Kỹ thuật & Dữ liệu | C6: =COUNTA('TIẾN ĐỘ TỔNG THỂ (ROADMAP)'!#REF!) -> 1 | D6: =COUNTIF('TIẾN ĐỘ TỔNG THỂ (ROADMAP)'!#REF!, "Đã hoàn thành") -> #REF! | E6: =COUNTIF('TIẾN ĐỘ TỔNG THỂ (ROADMAP)'!#REF!, "Đang thực hiện") -> #REF! | F6: =COUNTIF('TIẾN ĐỘ TỔNG THỂ (ROADMAP)'!#REF!, "Chậm tiến độ") -> #REF! | G6: =COUNTIF('TIẾN ĐỘ TỔNG THỂ (ROADMAP)'!#REF!, "Chưa thực hiện") -> #REF! | H6: =IFERROR(D6/C6, 0) -> 0 | I6: =IF(C6=0, "Chưa có việc", IF(F6>0, "⚠️ Có việc chậm trễ", IF(H6=1, "✅ Đã hoàn thành", "🟢 Đúng kế hoạch"))) -> #REF!
A7: 3 | B7: Dự án 03: AI RADAR IMPACT | C7: 5 | D7: 2 | E7: 3 | F7: =COUNTIF('TIẾN ĐỘ TỔNG THỂ (ROADMAP)'!G40:G42, "Chậm tiến độ") -> 0 | G7: =COUNTIF('TIẾN ĐỘ TỔNG THỂ (ROADMAP)'!G40:G42, "Chưa thực hiện") -> 0 | H7: =IFERROR(D7/C7, 0) -> 0.4 | I7: =IF(C7=0, "Chưa có việc", IF(F7>0, "⚠️ Có việc chậm trễ", IF(H7=1, "✅ Đã hoàn thành", "🟢 Đúng kế hoạch"))) -> 🟢 Đúng kế hoạch
A8: 4 | B8: Dự án 04: HỆ THỐNG TOKEN LEDGER | C8: =COUNTA('TIẾN ĐỘ TỔNG THỂ (ROADMAP)'!A46:A55) -> 10 | D8: =COUNTIF('TIẾN ĐỘ TỔNG THỂ (ROADMAP)'!G46:G55, "Đã hoàn thành") -> 9 | E8: =COUNTIF('TIẾN ĐỘ TỔNG THỂ (ROADMAP)'!G46:G55, "Đang thực hiện") -> 1 | F8: =COUNTIF('TIẾN ĐỘ TỔNG THỂ (ROADMAP)'!G46:G55, "Chậm tiến độ") -> 0 | G8: =COUNTIF('TIẾN ĐỘ TỔNG THỂ (ROADMAP)'!G46:G55, "Chưa thực hiện") -> 0 | H8: =IFERROR(D8/C8, 0) -> 0.9 | I8: =IF(C8=0, "Chưa có việc", IF(F8>0, "⚠️ Có việc chậm trễ", IF(H8=1, "✅ Đã hoàn thành", "🟢 Đúng kế hoạch"))) -> 🟢 Đúng kế hoạch
A9: 5 | B9: Dự án 05: Chăm sóc Khách hàng & Hỗ trợ Vận hành | C9: =COUNTA('TIẾN ĐỘ TỔNG THỂ (ROADMAP)'!A57:A58) -> 2 | D9: =COUNTIF('TIẾN ĐỘ TỔNG THỂ (ROADMAP)'!G57:G58, "Đã hoàn thành") -> 2 | E9: =COUNTIF('TIẾN ĐỘ TỔNG THỂ (ROADMAP)'!G57:G58, "Đang thực hiện") -> 0 | F9: =COUNTIF('TIẾN ĐỘ TỔNG THỂ (ROADMAP)'!G57:G58, "Chậm tiến độ") -> 0 | G9: =COUNTIF('TIẾN ĐỘ TỔNG THỂ (ROADMAP)'!G57:G58, "Chưa thực hiện") -> 0 | H9: =IFERROR(D9/C9, 0) -> 1 | I9: =IF(C9=0, "Chưa có việc", IF(F9>0, "⚠️ Có việc chậm trễ", IF(H9=1, "✅ Đã hoàn thành", "🟢 Đúng kế hoạch"))) -> ✅ Đã hoàn thành
B10: TỔNG CỘNG CÁC DỰ ÁN | C10: =SUM(C5:C9) -> 22 | D10: =SUM(D5:D9) -> #REF! | E10: =SUM(E5:E9) -> #REF! | F10: =SUM(F5:F9) -> #REF! | G10: =SUM(G5:G9) -> #REF! | H10: =IFERROR(D10/C10, 0) -> 0 | I10: -
A12: 2. PHÂN BỔ KHỐI LƯỢNG & TIẾN ĐỘ 4 THÀNH VIÊN
A13: STT | B13: Thành viên | C13: Đầu việc chính | D13: Đã xong | E13: Đang làm | F13: Chậm trễ | G13: Chưa làm | H13: Tiến độ % | I13: Đánh giá tải việc
A14: 1 | B14: An Thanh | C14: =COUNTIF('TIẾN ĐỘ TỔNG THỂ (ROADMAP)'!D8:D67, "An Thanh") -> 18 | D14: =COUNTIFS('TIẾN ĐỘ TỔNG THỂ (ROADMAP)'!D8:D67, "An Thanh", 'TIẾN ĐỘ TỔNG THỂ (ROADMAP)'!G8:G67, "Đã hoàn thành") -> 12 | E14: =COUNTIFS('TIẾN ĐỘ TỔNG THỂ (ROADMAP)'!D8:D67, "An Thanh", 'TIẾN ĐỘ TỔNG THỂ (ROADMAP)'!G8:G67, "Đang thực hiện") -> 4 | F14: =COUNTIFS('TIẾN ĐỘ TỔNG THỂ (ROADMAP)'!D8:D67, "An Thanh", 'TIẾN ĐỘ TỔNG THỂ (ROADMAP)'!G8:G67, "Chậm tiến độ") -> 0 | G14: =COUNTIFS('TIẾN ĐỘ TỔNG THỂ (ROADMAP)'!D8:D67, "An Thanh", 'TIẾN ĐỘ TỔNG THỂ (ROADMAP)'!G8:G67, "Chưa thực hiện") -> 1 | H14: =IFERROR(D14/C14, 0) -> 0.66666667 | I14: =IF(C14>=5, "⚡ Tải cao", IF(F14>0, "⚠️ Có việc trễ", "🟢 Tiến độ tốt")) -> ⚡ Tải cao
A15: 2 | B15: Chí Thanh | C15: =COUNTIF('TIẾN ĐỘ TỔNG THỂ (ROADMAP)'!D8:D67, "Chí Thanh") -> 10 | D15: =COUNTIFS('TIẾN ĐỘ TỔNG THỂ (ROADMAP)'!D8:D67, "Chí Thanh", 'TIẾN ĐỘ TỔNG THỂ (ROADMAP)'!G8:G67, "Đã hoàn thành") -> 9 | E15: =COUNTIFS('TIẾN ĐỘ TỔNG THỂ (ROADMAP)'!D8:D67, "Chí Thanh", 'TIẾN ĐỘ TỔNG THỂ (ROADMAP)'!G8:G67, "Đang thực hiện") -> 1 | F15: =COUNTIFS('TIẾN ĐỘ TỔNG THỂ (ROADMAP)'!D8:D67, "Chí Thanh", 'TIẾN ĐỘ TỔNG THỂ (ROADMAP)'!G8:G67, "Chậm tiến độ") -> 0 | G15: =COUNTIFS('TIẾN ĐỘ TỔNG THỂ (ROADMAP)'!D8:D67, "Chí Thanh", 'TIẾN ĐỘ TỔNG THỂ (ROADMAP)'!G8:G67, "Chưa thực hiện") -> 0 | H15: =IFERROR(D15/C15, 0) -> 0.9 | I15: =IF(C15>=5, "⚡ Tải cao", IF(F15>0, "⚠️ Có việc trễ", "🟢 Tiến độ tốt")) -> ⚡ Tải cao
A16: 3 | B16: Tuấn | C16: =COUNTIF('TIẾN ĐỘ TỔNG THỂ (ROADMAP)'!D8:D67, "Tuấn") -> 14 | D16: =COUNTIFS('TIẾN ĐỘ TỔNG THỂ (ROADMAP)'!D8:D67, "Tuấn", 'TIẾN ĐỘ TỔNG THỂ (ROADMAP)'!G8:G67, "Đã hoàn thành") -> 14 | E16: =COUNTIFS('TIẾN ĐỘ TỔNG THỂ (ROADMAP)'!D8:D67, "Tuấn", 'TIẾN ĐỘ TỔNG THỂ (ROADMAP)'!G8:G67, "Đang thực hiện") -> 0 | F16: =COUNTIFS('TIẾN ĐỘ TỔNG THỂ (ROADMAP)'!D8:D67, "Tuấn", 'TIẾN ĐỘ TỔNG THỂ (ROADMAP)'!G8:G67, "Chậm tiến độ") -> 0 | G16: =COUNTIFS('TIẾN ĐỘ TỔNG THỂ (ROADMAP)'!D8:D67, "Tuấn", 'TIẾN ĐỘ TỔNG THỂ (ROADMAP)'!G8:G67, "Chưa thực hiện") -> 0 | H16: =IFERROR(D16/C16, 0) -> 1 | I16: =IF(C16>=5, "⚡ Tải cao", IF(F16>0, "⚠️ Có việc trễ", "🟢 Tiến độ tốt")) -> ⚡ Tải cao
A17: 4 | B17: Hưng | C17: =COUNTIF('TIẾN ĐỘ TỔNG THỂ (ROADMAP)'!D8:D67, "Hưng") -> 13 | D17: =COUNTIFS('TIẾN ĐỘ TỔNG THỂ (ROADMAP)'!D8:D67, "Hưng", 'TIẾN ĐỘ TỔNG THỂ (ROADMAP)'!G8:G67, "Đã hoàn thành") -> 11 | E17: =COUNTIFS('TIẾN ĐỘ TỔNG THỂ (ROADMAP)'!D8:D67, "Hưng", 'TIẾN ĐỘ TỔNG THỂ (ROADMAP)'!G8:G67, "Đang thực hiện") -> 0 | F17: =COUNTIFS('TIẾN ĐỘ TỔNG THỂ (ROADMAP)'!D8:D67, "Hưng", 'TIẾN ĐỘ TỔNG THỂ (ROADMAP)'!G8:G67, "Chậm tiến độ") -> 0 | G17: =COUNTIFS('TIẾN ĐỘ TỔNG THỂ (ROADMAP)'!D8:D67, "Hưng", 'TIẾN ĐỘ TỔNG THỂ (ROADMAP)'!G8:G67, "Chưa thực hiện") -> 0 | H17: =IFERROR(D17/C17, 0) -> 0.84615385 | I17: =IF(C17>=5, "⚡ Tải cao", IF(F17>0, "⚠️ Có việc trễ", "🟢 Tiến độ tốt")) -> ⚡ Tải cao
B18: TỔNG CỘNG NHÓM | C18: =SUM(C14:C17) -> 55 | D18: =SUM(D14:D17) -> 46 | E18: =SUM(E14:E17) -> 5 | F18: =SUM(F14:F17) -> 0 | G18: =SUM(G14:G17) -> 1 | H18: =IFERROR(D18/C18, 0) -> 0.83636364 | I18: -
